Workbook
Name Cat_Nombre: Parametros!$A$5:$A$8
Name Cat_HMin: Parametros!$C$5:$C$8
Name Cat_HMax: Parametros!$D$5:$D$8
Name Cat_TMin: Parametros!$E$5:$E$8
Name Cat_TMax: Parametros!$F$5:$F$8
Name Cat_POpus: Parametros!$G$5:$G$8
Name UsdM_Sonnet: Parametros!$F$13
Name UsdM_Opus: Parametros!$F$14
Name TipoCambio: Parametros!$B$20
Name MonedaCliente: Parametros!$B$21
Name PerfilSel: Parametros!$B$22
Name TarifaHora: Parametros!$B$26
Name HorasDia: Parametros!$B$27
Name FactorColchon: Parametros!$B$30
Name Margen: Parametros!$B$31
Name Perfil_Clave: Parametros!$F$35:$F$54
Name Perfil_SueldoUSD: Parametros!$E$35:$E$54
Name Perfil_Lista: OFFSET(Parametros!$F$35,0,0,MAX(1,COUNTIF(Parametros!$F$35:$F$54,"?*")),1)

Sheet Instrucciones
A1: Cotizador de proyectos de software (metodología de estimación)
A3: Uso rápido
A4: 1. Copia el texto de la hoja 'Prompt IA', pégalo en tu LLM y agrega al final el alcance del proyecto.
A5: 2. El LLM devuelve un bloque de texto separado por tabulaciones (Hito, Feature, Categoría, Confirmado), sin encabezado.
A6: 3. Borra los datos de ejemplo de 'Features' (selecciona A2:E501 y pulsa Supr; no elimines filas) y pega en la celda A2.
A7: Si todo queda en una sola columna: Datos > Texto en columnas > Delimitados > Tabulación.
A8: 4. Revisa la columna 'Estado' en 'Features': todas las filas con datos deben decir OK.
A9: 5. Resultado: 'Cotización' (uso interno, rangos y costos) y 'Propuesta cliente' (solo días comprometidos y precio por hito).
A11: Qué se puede editar
A12: • Celdas amarillas = entradas. Celdas grises = fórmulas (no tocar).
A13: • 'Parametros': horas y tokens por categoría, % de tokens en Opus, precios de Copilot, mezcla de tokens,
A14: tipo de cambio, moneda de la propuesta (USD/PEN), perfil de sueldo, horas efectivas por día, colchón y margen.
... A31: Capacidad: 500 features y 50 hitos. El nombre del hito debe repetirse igual en cada feature.

Sheet Parametros
A1: Parámetros de la metodología
A3: 1. Categorías de complejidad
A4: Categoría | B4: Modelo principal | C4: Horas mín | D4: Horas máx | E4: Tokens mín | F4: Tokens máx | G4: % tokens en Opus | H4: Turnos típicos (ref.) | I4: Tokens/turno (ref.)
A5: Simple | B5: Sonnet | C5: 1 | D5: 1.5 | E5: 80000 | F5: 150000 | G5: 0 | H5: 6–10 | I5: 8k–15k
A6: Moderado | B6: Sonnet (revisión puntual en Opus) | C6: 2 | D6: 3 | E6: 150000 | F6: 300000 | G6: 0 | H6: 10–16 | I6: 12k–20k
A7: Complejo | B7: Opus (diseño) + Sonnet (detalle) | C7: 4 | D7: 8 | E7: 400000 | F7: 900000 | G7: 0.5 | H7: 16–28 | I7: 20k–40k
A8: Complejo primera vez | B8: Opus | C8: 8 | D8: 16 | E8: 600000 | F8: 1200000 | G8: 1 | H8: 20–35 | I8: 25k–45k
A9: Horas de Complejo / Complejo primera vez = días × 4 h (1–2 días y 2–4 días de la metodología).
A11: 2. Precios GitHub Copilot (créditos por millón de tokens)
A12: Modelo | B12: Input | C12: Output | D12: Cache read | E12: Cache write | F12: USD / M tokens (mezcla)
A13: Sonnet | B13: 200 | C13: 1000 | D13: 20 | E13: 250 | F13: =SUMPRODUCT(B13:E13,$B$15:$E$15)/$B$17
A14: Opus | B14: 500 | C14: 2500 | D14: 50 | E14: 625 | F14: =SUMPRODUCT(B14:E14,$B$15:$E$15)/$B$17
A15: Mezcla de tokens (% del total) | B15: 0.15 | C15: 0.15 | D15: 0.55 | E15: 0.15 | F15: =IF(ROUND(SUM(B15:E15),4)=1,"OK (100%)","⚠ Debe sumar 100%")
A17: Créditos por USD | B17: 100
A19: 3. Desarrollador y moneda
A20: Tipo de cambio (PEN por 1 USD) | B20: 3.7 | C20: Actualizar al tipo de cambio del día.
A21: Moneda de la propuesta al cliente | B21: USD | C21: USD o PEN. Solo afecta la hoja 'Propuesta cliente'.
A22: Perfil de sueldo | B22: Backend senior / arquitecto | Internacional | C22: Elegir de la tabla '5. Perfiles de sueldo' (o 'Custom').
A23: Sueldo mensual seleccionado (USD) | B23: =IFERROR(INDEX(Perfil_SueldoUSD,MATCH(PerfilSel,Perfil_Clave,0)),"⚠ Perfil no encontrado") | C23: Calculado desde el perfil (convertido a USD si está en PEN).
A24: Días laborables por mes | B24: 20
A25: Horas de jornada completa | B25: 8 | C25: Jornada con la que se calcula el sueldo (no la del proyecto).
A26: Tarifa por hora (USD) | B26: =B23/(B24*B25) | C26: Calculado.
A27: Horas efectivas por día dedicadas al proyecto | B27: 4 | C27: Restricción de agenda; convierte horas en días.
A29: 4. Compromiso y precio
A30: Factor de colchón por hito (0–1) | B30: 0.5 | C30: Días comprometidos = promedio + factor × (pesimista − promedio). Subir si sueles pasarte, bajar si terminas antes.
A31: Margen adicional sobre precio | B31: 0 | C31: Precio sugerido = (costo tiempo comprometido + costo IA máx.) × (1 + margen).
A33: 5. Perfiles de sueldo (agregar filas nuevas debajo, sin dejar filas vacías en medio)
A34: Perfil | B34: Mercado | C34: Moneda | D34: Sueldo mensual | E34: Sueldo mensual (USD) | F34: Nombre en el selector
A35: Backend senior / arquitecto | B35: Internacional | C35: USD | D35: 7000 | E35: =IF(D35="","",IF(C35="PEN",D35/TipoCambio,D35)) | F35: =IF(A35="","",IF(B35="",A35,A35&" | "&B35))
A36: Backend senior / arquitecto | B36: Perú | C36: PEN | D36: 15000 | E36: =IF(D36="","",IF(C36="PEN",D36/TipoCambio,D36)) | F36: =IF(A36="","",IF(B36="",A36,A36&" | "&B36))
A37: Fullstack | B37: Internacional | C37: USD | D37: 5000 | E37: =IF(D37="","",IF(C37="PEN",D37/TipoCambio,D37)) | F37: =IF(A37="","",IF(B37="",A37,A37&" | "&B37))
A38: Fullstack | B38: Perú | C38: PEN | D38: 10000 | E38: =IF(D38="","",IF(C38="PEN",D38/TipoCambio,D38)) | F38: =IF(A38="","",IF(B38="",A38,A38&" | "&B38))
A39: Landing page | B39: Internacional | C39: USD | D39: 3000 | E39: =IF(D39="","",IF(C39="PEN",D39/TipoCambio,D39)) | F39: =IF(A39="","",IF(B39="",A39,A39&" | "&B39))
A40: Landing page | B40: Perú | C40: PEN | D40: 5000 | E40: =IF(D40="","",IF(C40="PEN",D40/TipoCambio,D40)) | F40: =IF(A40="","",IF(B40="",A40,A40&" | "&B40))
A41: Consultor | B41: Internacional | C41: USD | D41: 9000 | E41: =IF(D41="","",IF(C41="PEN",D41/TipoCambio,D41)) | F41: =IF(A41="","",IF(B41="",A41,A41&" | "&B41))
A42: Consultor | B42: Perú | C42: PEN | D42: 20000 | E42: =IF(D42="","",IF(C42="PEN",D42/TipoCambio,D42)) | F42: =IF(A42="","",IF(B42="",A42,A42&" | "&B42))
A43: Custom | C43: USD | D43: 7000 | E43: =IF(D43="","",IF(C43="PEN",D43/TipoCambio,D43)) | F43: =IF(A43="","",IF(B43="",A43,A43&" | "&B43))
E44: =IF(D44="","",IF(C44="PEN",D44/TipoCambio,D44)) | F44: =IF(A44="","",IF(B44="",A44,A44&" | "&B44))
E45: =IF(D45="","",IF(C45="PEN",D45/TipoCambio,D45)) | F45: =IF(A45="","",IF(B45="",A45,A45&" | "&B45))
E46: =IF(D46="","",IF(C46="PEN",D46/TipoCambio,D46)) | F46: =IF(A46="","",IF(B46="",A46,A46&" | "&B46))
...

Sheet Features
A1: Hito | B1: Feature | C1: Categoría | D1: Confirmado (Sí/No) | E1: Notas (opcional) | F1: Estado | G1: Horas mín | H1: Horas máx | I1: Horas prom. | J1: Días mín | K1: Días prom. | L1: Días máx | M1: Tokens mín | N1: Tokens máx | O1: % Opus | P1: Costo IA mín | Q1: Costo IA máx | R1: Costo tiempo mín | S1: Costo tiempo máx | T1: idx hito
A2: Hito 0 - Configuración inicial | B2: Scaffold del proyecto y repositorio | C2: Complejo primera vez | D2: Sí | F2: =IF(AND($A2="",$B2="",$C2=""),"",IF($A2="","⚠ Falta hito",IF(ISNA(MATCH($C2,Cat_Nombre,0)),"⚠ Categoría inválida","OK"))) | G2: =IF($F2<>"OK","",IF(UPPER(TRIM($D2))="NO",INDEX(Cat_HMax,MATCH($C2,Cat_Nombre,0)),INDEX(Cat_HMin,MATCH($C2,Cat_Nombre,0)))) | H2: =IF($F2<>"OK","",INDEX(Cat_HMax,MATCH($C2,Cat_Nombre,0))) | I2: =IF($F2<>"OK","",(G2+H2)/2) | J2: =IF($F2<>"OK","",G2/HorasDia) | K2: =IF($F2<>"OK","",I2/HorasDia) | L2: =IF($F2<>"OK","",H2/HorasDia) | M2: =IF($F2<>"OK","",IF(UPPER(TRIM($D2))="NO",INDEX(Cat_TMax,MATCH($C2,Cat_Nombre,0)),INDEX(Cat_TMin,MATCH($C2,Cat_Nombre,0)))) | N2: =IF($F2<>"OK","",INDEX(Cat_TMax,MATCH($C2,Cat_Nombre,0))) | O2: =IF($F2<>"OK","",INDEX(Cat_POpus,MATCH($C2,Cat_Nombre,0))) | P2: =IF($F2<>"OK","",M2/1000000*((1-O2)*UsdM_Sonnet+O2*UsdM_Opus)) | Q2: =IF($F2<>"OK","",N2/1000000*((1-O2)*UsdM_Sonnet+O2*UsdM_Opus)) | R2: =IF($F2<>"OK","",G2*TarifaHora) | S2: =IF($F2<>"OK","",H2*TarifaHora) | T2: =IF($F2<>"OK","",IF(COUNTIFS($A$2:$A2,$A2,$F$2:$F2,"OK")=1,MAX($T$1:$T1)+1,""))
A3: Hito 0 - Configuración inicial | B3: Autenticación de usuarios | C3: Complejo primera vez | D3: Sí | F3: =IF(AND($A3="",$B3="",$C3=""),"",IF($A3="","⚠ Falta hito",IF(ISNA(MATCH($C3,Cat_Nombre,0)),"⚠ Categoría inválida","OK"))) | G3: =IF($F3<>"OK","",IF(UPPER(TRIM($D3))="NO",INDEX(Cat_HMax,MATCH($C3,Cat_Nombre,0)),INDEX(Cat_HMin,MATCH($C3,Cat_Nombre,0)))) | H3: =IF($F3<>"OK","",INDEX(Cat_HMax,MATCH($C3,Cat_Nombre,0))) | I3: =IF($F3<>"OK","",(G3+H3)/2) | J3: =IF($F3<>"OK","",G3/HorasDia) | K3: =IF($F3<>"OK","",I3/HorasDia) | L3: =IF($F3<>"OK","",H3/HorasDia) | M3: =IF($F3<>"OK","",IF(UPPER(TRIM($D3))="NO",INDEX(Cat_TMax,MATCH($C3,Cat_Nombre,0)),INDEX(Cat_TMin,MATCH($C3,Cat_Nombre,0)))) | N3: =IF($F3<>"OK","",INDEX(Cat_TMax,MATCH($C3,Cat_Nombre,0))) | O3: =IF($F3<>"OK","",INDEX(Cat_POpus,MATCH($C3,Cat_Nombre,0))) | P3: =IF($F3<>"OK","",M3/1000000*((1-O3)*UsdM_Sonnet+O3*UsdM_Opus)) | Q3: =IF($F3<>"OK","",N3/1000000*((1-O3)*UsdM_Sonnet+O3*UsdM_Opus)) | R3: =IF($F3<>"OK","",G3*TarifaHora) | S3: =IF($F3<>"OK","",H3*TarifaHora) | T3: =IF($F3<>"OK","",IF(COUNTIFS($A$2:$A3,$A3,$F$2:$F3,"OK")=1,MAX($T$1:$T2)+1,""))
A4: Hito 0 - Configuración inicial | B4: Despliegue en hosting con CI/CD | C4: Complejo primera vez | D4: Sí | F4: =IF(AND($A4="",$B4="",$C4=""),"",IF($A4="","⚠ Falta hito",IF(ISNA(MATCH($C4,Cat_Nombre,0)),"⚠ Categoría inválida","OK"))) | G4: =IF($F4<>"OK","",IF(UPPER(TRIM($D4))="NO",INDEX(Cat_HMax,MATCH($C4,Cat_Nombre,0)),INDEX(Cat_HMin,MATCH($C4,Cat_Nombre,0)))) | H4: =IF($F4<>"OK","",INDEX(Cat_HMax,MATCH($C4,Cat_Nombre,0))) | I4: =IF($F4<>"OK","",(G4+H4)/2) | J4: =IF($F4<>"OK","",G4/HorasDia) | K4: =IF($F4<>"OK","",I4/HorasDia) | L4: =IF($F4<>"OK","",H4/HorasDia) | M4: =IF($F4<>"OK","",IF(UPPER(TRIM($D4))="NO",INDEX(Cat_TMax,MATCH($C4,Cat_Nombre,0)),INDEX(Cat_TMin,MATCH($C4,Cat_Nombre,0)))) | N4: =IF($F4<>"OK","",INDEX(Cat_TMax,MATCH($C4,Cat_Nombre,0))) | O4: =IF($F4<>"OK","",INDEX(Cat_POpus,MATCH($C4,Cat_Nombre,0))) | P4: =IF($F4<>"OK","",M4/1000000*((1-O4)*UsdM_Sonnet+O4*UsdM_Opus)) | Q4: =IF($F4<>"OK","",N4/1000000*((1-O4)*UsdM_Sonnet+O4*UsdM_Opus)) | R4: =IF($F4<>"OK","",G4*TarifaHora) | S4: =IF($F4<>"OK","",H4*TarifaHora) | T4: =IF($F4<>"OK","",IF(COUNTIFS($A$2:$A4,$A4,$F$2:$F4,"OK")=1,MAX($T$1:$T3)+1,""))
A5: Hito 1 - Clientes y gastos | B5: CRUD de clientes | C5: Moderado | D5: Sí | F5: =IF(AND($A5="",$B5="",$C5=""),"",IF($A5="","⚠ Falta hito",IF(ISNA(MATCH($C5,Cat_Nombre,0)),"⚠ Categoría inválida","OK"))) | G5: =IF($F5<>"OK","",IF(UPPER(TRIM($D5))="NO",INDEX(Cat_HMax,MATCH($C5,Cat_Nombre,0)),INDEX(Cat_HMin,MATCH($C5,Cat_Nombre,0)))) | H5: =IF($F5<>"OK","",INDEX(Cat_HMax,MATCH($C5,Cat_Nombre,0))) | I5: =IF($F5<>"OK","",(G5+H5)/2) | J5: =IF($F5<>"OK","",G5/HorasDia) | K5: =IF($F5<>"OK","",I5/HorasDia) | L5: =IF($F5<>"OK","",H5/HorasDia) | M5: =IF($F5<>"OK","",IF(UPPER(TRIM($D5))="NO",INDEX(Cat_TMax,MATCH($C5,Cat_Nombre,0)),INDEX(Cat_TMin,MATCH($C5,Cat_Nombre,0)))) | N5: =IF($F5<>"OK","",INDEX(Cat_TMax,MATCH($C5,Cat_Nombre,0))) | O5: =IF($F5<>"OK","",INDEX(Cat_POpus,MATCH($C5,Cat_Nombre,0))) | P5: =IF($F5<>"OK","",M5/1000000*((1-O5)*UsdM_Sonnet+O5*UsdM_Opus)) | Q5: =IF($F5<>"OK","",N5/1000000*((1-O5)*UsdM_Sonnet+O5*UsdM_Opus)) | R5: =IF($F5<>"OK","",G5*TarifaHora) | S5: =IF($F5<>"OK","",H5*TarifaHora) | T5: =IF($F5<>"OK","",IF(COUNTIFS($A$2:$A5,$A5,$F$2:$F5,"OK")=1,MAX($T$1:$T4)+1,""))
A6: Hito 1 - Clientes y gastos | B6: CRUD de proveedores | C6: Simple | D6: Sí | F6: =IF(AND($A6="",$B6="",$C6=""),"",IF($A6="","⚠ Falta hito",IF(ISNA(MATCH($C6,Cat_Nombre,0)),"⚠ Categoría inválida","OK"))) | G6: =IF($F6<>"OK","",IF(UPPER(TRIM($D6))="NO",INDEX(Cat_HMax,MATCH($C6,Cat_Nombre,0)),INDEX(Cat_HMin,MATCH($C6,Cat_Nombre,0)))) | H6: =IF($F6<>"OK","",INDEX(Cat_HMax,MATCH($C6,Cat_Nombre,0))) | I6: =IF($F6<>"OK","",(G6+H6)/2) | J6: =IF($F6<>"OK","",G6/HorasDia) | K6: =IF($F6<>"OK","",I6/HorasDia) | L6: =IF($F6<>"OK","",H6/HorasDia) | M6: =IF($F6<>"OK","",IF(UPPER(TRIM($D6))="NO",INDEX(Cat_TMax,MATCH($C6,Cat_Nombre,0)),INDEX(Cat_TMin,MATCH($C6,Cat_Nombre,0)))) | N6: =IF($F6<>"OK","",INDEX(Cat_TMax,MATCH($C6,Cat_Nombre,0))) | O6: =IF($F6<>"OK","",INDEX(Cat_POpus,MATCH($C6,Cat_Nombre,0))) | P6: =IF($F6<>"OK","",M6/1000000*((1-O6)*UsdM_Sonnet+O6*UsdM_Opus)) | Q6: =IF($F6<>"OK","",N6/1000000*((1-O6)*UsdM_Sonnet+O6*UsdM_Opus)) | R6: =IF($F6<>"OK","",G6*TarifaHora) | S6: =IF($F6<>"OK","",H6*TarifaHora) | T6: =IF($F6<>"OK","",IF(COUNTIFS($A$2:$A6,$A6,$F$2:$F6,"OK")=1,MAX($T$1:$T5)+1,""))
A7: Hito 1 - Clientes y gastos | B7: Motor de alertas de gasto vs. presupuesto | C7: Complejo | D7: No | F7: =IF(AND($A7="",$B7="",$C7=""),"",IF($A7="","⚠ Falta hito",IF(ISNA(MATCH($C7,Cat_Nombre,0)),"⚠ Categoría inválida","OK"))) | G7: =IF($F7<>"OK","",IF(UPPER(TRIM($D7))="NO",INDEX(Cat_HMax,MATCH($C7,Cat_Nombre,0)),INDEX(Cat_HMin,MATCH($C7,Cat_Nombre,0)))) | H7: =IF($F7<>"OK","",INDEX(Cat_HMax,MATCH($C7,Cat_Nombre,0))) | I7: =IF($F7<>"OK","",(G7+H7)/2) | J7: =IF($F7<>"OK","",G7/HorasDia) | K7: =IF($F7<>"OK","",I7/HorasDia) | L7: =IF($F7<>"OK","",H7/HorasDia) | M7: =IF($F7<>"OK","",IF(UPPER(TRIM($D7))="NO",INDEX(Cat_TMax,MATCH($C7,Cat_Nombre,0)),INDEX(Cat_TMin,MATCH($C7,Cat_Nombre,0)))) | N7: =IF($F7<>"OK","",INDEX(Cat_TMax,MATCH($C7,Cat_Nombre,0))) | O7: =IF($F7<>"OK","",INDEX(Cat_POpus,MATCH($C7,Cat_Nombre,0))) | P7: =IF($F7<>"OK","",M7/1000000*((1-O7)*UsdM_Sonnet+O7*UsdM_Opus)) | Q7: =IF($F7<>"OK","",N7/1000000*((1-O7)*UsdM_Sonnet+O7*UsdM_Opus)) | R7: =IF($F7<>"OK","",G7*TarifaHora) | S7: =IF($F7<>"OK","",H7*TarifaHora) | T7: =IF($F7<>"OK","",IF(COUNTIFS($A$2:$A7,$A7,$F$2:$F7,"OK")=1,MAX($T$1:$T6)+1,""))
A8: Hito 2 - Reportes | B8: Reporte mensual exportable a PDF | C8: Moderado | D8: Sí | F8: =IF(AND($A8="",$B8="",$C8=""),"",IF($A8="","⚠ Falta hito",IF(ISNA(MATCH($C8,Cat_Nombre,0)),"⚠ Categoría inválida","OK"))) | G8: =IF($F8<>"OK","",IF(UPPER(TRIM($D8))="NO",INDEX(Cat_HMax,MATCH($C8,Cat_Nombre,0)),INDEX(Cat_HMin,MATCH($C8,Cat_Nombre,0)))) | H8: =IF($F8<>"OK","",INDEX(Cat_HMax,MATCH($C8,Cat_Nombre,0))) | I8: =IF($F8<>"OK","",(G8+H8)/2) | J8: =IF($F8<>"OK","",G8/HorasDia) | K8: =IF($F8<>"OK","",I8/HorasDia) | L8: =IF($F8<>"OK","",H8/HorasDia) | M8: =IF($F8<>"OK","",IF(UPPER(TRIM($D8))="NO",INDEX(Cat_TMax,MATCH($C8,Cat_Nombre,0)),INDEX(Cat_TMin,MATCH($C8,Cat_Nombre,0)))) | N8: =IF($F8<>"OK","",INDEX(Cat_TMax,MATCH($C8,Cat_Nombre,0))) | O8: =IF($F8<>"OK","",INDEX(Cat_POpus,MATCH($C8,Cat_Nombre,0))) | P8: =IF($F8<>"OK","",M8/1000000*((1-O8)*UsdM_Sonnet+O8*UsdM_Opus)) | Q8: =IF($F8<>"OK","",N8/1000000*((1-O8)*UsdM_Sonnet+O8*UsdM_Opus)) | R8: =IF($F8<>"OK","",G8*TarifaHora) | S8: =IF($F8<>"OK","",H8*TarifaHora) | T8: =IF($F8<>"OK","",IF(COUNTIFS($A$2:$A8,$A8,$F$2:$F8,"OK")=1,MAX($T$1:$T7)+1,""))
A9: Hito 2 - Reportes | B9: Dashboard de indicadores | C9: Moderado | D9: No | F9: =IF(AND($A9="",$B9="",$C9=""),"",IF($A9="","⚠ Falta hito",IF(ISNA(MATCH($C9,Cat_Nombre,0)),"⚠ Categoría inválida","OK"))) | G9: =IF($F9<>"OK","",IF(UPPER(TRIM($D9))="NO",INDEX(Cat_HMax,MATCH($C9,Cat_Nombre,0)),INDEX(Cat_HMin,MATCH($C9,Cat_Nombre,0)))) | H9: =IF($F9<>"OK","",INDEX(Cat_HMax,MATCH($C9,Cat_Nombre,0))) | I9: =IF($F9<>"OK","",(G9+H9)/2) | J9: =IF($F9<>"OK","",G9/HorasDia) | K9: =IF($F9<>"OK","",I9/HorasDia) | L9: =IF($F9<>"OK","",H9/HorasDia) | M9: =IF($F9<>"OK","",IF(UPPER(TRIM($D9))="NO",INDEX(Cat_TMax,MATCH($C9,Cat_Nombre,0)),INDEX(Cat_TMin,MATCH($C9,Cat_Nombre,0)))) | N9: =IF($F9<>"OK","",INDEX(Cat_TMax,MATCH($C9,Cat_Nombre,0))) | O9: =IF($F9<>"OK","",INDEX(Cat_POpus,MATCH($C9,Cat_Nombre,0))) | P9: =IF($F9<>"OK","",M9/1000000*((1-O9)*UsdM_Sonnet+O9*UsdM_Opus)) | Q9: =IF($F9<>"OK","",N9/1000000*((1-O9)*UsdM_Sonnet+O9*UsdM_Opus)) | R9: =IF($F9<>"OK","",G9*TarifaHora) | S9: =IF($F9<>"OK","",H9*TarifaHora) | T9: =IF($F9<>"OK","",IF(COUNTIFS($A$2:$A9,$A9,$F$2:$F9,"OK")=1,MAX($T$1:$T8)+1,""))
F10: =IF(AND($A10="",$B10="",$C10=""),"",IF($A10="","⚠ Falta hito",IF(ISNA(MATCH($C10,Cat_Nombre,0)),"⚠ Categoría inválida","OK"))) | G10: =IF($F10<>"OK","",IF(UPPER(TRIM($D10))="NO",INDEX(Cat_HMax,MATCH($C10,Cat_Nombre,0)),INDEX(Cat_HMin,MATCH($C10,Cat_Nombre,0)))) | H10: =IF($F10<>"OK","",INDEX(Cat_HMax,MATCH($C10,Cat_Nombre,0))) | I10: =IF($F10<>"OK","",(G10+H10)/2) | J10: =IF($F10<>"OK","",G10/HorasDia) | K10: =IF($F10<>"OK","",I10/HorasDia) | L10: =IF($F10<>"OK","",H10/HorasDia) | M10: =IF($F10<>"OK","",IF(UPPER(TRIM($D10))="NO",INDEX(Cat_TMax,MATCH($C10,Cat_Nombre,0)),INDEX(Cat_TMin,MATCH($C10,Cat_Nombre,0)))) | N10: =IF($F10<>"OK","",INDEX(Cat_TMax,MATCH($C10,Cat_Nombre,0))) | O10: =IF($F10<>"OK","",INDEX(Cat_POpus,MATCH($C10,Cat_Nombre,0))) | P10: =IF($F10<>"OK","",M10/1000000*((1-O10)*UsdM_Sonnet+O10*UsdM_Opus)) | Q10: =IF($F10<>"OK","",N10/1000000*((1-O10)*UsdM_Sonnet+O10*UsdM_Opus)) | R10: =IF($F10<>"OK","",G10*TarifaHora) | S10: =IF($F10<>"OK","",H10*TarifaHora) | T10: =IF($F10<>"OK","",IF(COUNTIFS($A$2:$A10,$A10,$F$2:$F10,"OK")=1,MAX($T$1:$T9)+1,""))
F11: =IF(AND($A11="",$B11="",$C11=""),"",IF($A11="","⚠ Falta hito",IF(ISNA(MATCH($C11,Cat_Nombre,0)),"⚠ Categoría inválida","OK"))) | G11: =IF($F11<>"OK","",IF(UPPER(TRIM($D11))="NO",INDEX(Cat_HMax,MATCH($C11,Cat_Nombre,0)),INDEX(Cat_HMin,MATCH($C11,Cat_Nombre,0)))) | H11: =IF($F11<>"OK","",INDEX(Cat_HMax,MATCH($C11,Cat_Nombre,0))) | I11: =IF($F11<>"OK","",(G11+H11)/2) | J11: =IF($F11<>"OK","",G11/HorasDia) | K11: =IF($F11<>"OK","",I11/HorasDia) | L11: =IF($F11<>"OK","",H11/HorasDia) | M11: =IF($F11<>"OK","",IF(UPPER(TRIM($D11))="NO",INDEX(Cat_TMax,MATCH($C11,Cat_Nombre,0)),INDEX(Cat_TMin,MATCH($C11,Cat_Nombre,0)))) | N11: =IF($F11<>"OK","",INDEX(Cat_TMax,MATCH($C11,Cat_Nombre,0))) | O11: =IF($F11<>"OK","",INDEX(Cat_POpus,MATCH($C11,Cat_Nombre,0))) | P11: =IF($F11<>"OK","",M11/1000000*((1-O11)*UsdM_Sonnet+O11*UsdM_Opus)) | Q11: =IF($F11<>"OK","",N11/1000000*((1-O11)*UsdM_Sonnet+O11*UsdM_Opus)) | R11: =IF($F11<>"OK","",G11*TarifaHora) | S11: =IF($F11<>"OK","",H11*TarifaHora) | T11: =IF($F11<>"OK","",IF(COUNTIFS($A$2:$A11,$A11,$F$2:$F11,"OK")=1,MAX($T$1:$T10)+1,""))
F12: =IF(AND($A12="",$B12="",$C12=""),"",IF($A12="","⚠ Falta hito",IF(ISNA(MATCH($C12,Cat_Nombre,0)),"⚠ Categoría inválida","OK"))) | G12: =IF($F12<>"OK","",IF(UPPER(TRIM($D12))="NO",INDEX(Cat_HMax,MATCH($C12,Cat_Nombre,0)),INDEX(Cat_HMin,MATCH($C12,Cat_Nombre,0)))) | H12: =IF($F12<>"OK","",INDEX(Cat_HMax,MATCH($C12,Cat_Nombre,0))) | I12: =IF($F12<>"OK","",(G12+H12)/2) | J12: =IF($F12<>"OK","",G12/HorasDia) | K12: =IF($F12<>"OK","",I12/HorasDia) | L12: =IF($F12<>"OK","",H12/HorasDia) | M12: =IF($F12<>"OK","",IF(UPPER(TRIM($D12))="NO",INDEX(Cat_TMax,MATCH($C12,Cat_Nombre,0)),INDEX(Cat_TMin,MATCH($C12,Cat_Nombre,0)))) | N12: =IF($F12<>"OK","",INDEX(Cat_TMax,MATCH($C12,Cat_Nombre,0))) | O12: =IF($F12<>"OK","",INDEX(Cat_POpus,MATCH($C12,Cat_Nombre,0))) | P12: =IF($F12<>"OK","",M12/1000000*((1-O12)*UsdM_Sonnet+O12*UsdM_Opus)) | Q12: =IF($F12<>"OK","",N12/1000000*((1-O12)*UsdM_Sonnet+O12*UsdM_Opus)) | R12: =IF($F12<>"OK","",G12*TarifaHora) | S12: =IF($F12<>"OK","",H12*TarifaHora) | T12: =IF($F12<>"OK","",IF(COUNTIFS($A$2:$A12,$A12,$F$2:$F12,"OK")=1,MAX($T$1:$T11)+1,""))
F13: =IF(AND($A13="",$B13="",$C13=""),"",IF($A13="","⚠ Falta hito",IF(ISNA(MATCH($C13,Cat_Nombre,0)),"⚠ Categoría inválida","OK"))) | G13: =IF($F13<>"OK","",IF(UPPER(TRIM($D13))="NO",INDEX(Cat_HMax,MATCH($C13,Cat_Nombre,0)),INDEX(Cat_HMin,MATCH($C13,Cat_Nombre,0)))) | H13: =IF($F13<>"OK","",INDEX(Cat_HMax,MATCH($C13,Cat_Nombre,0))) | I13: =IF($F13<>"OK","",(G13+H13)/2) | J13: =IF($F13<>"OK","",G13/HorasDia) | K13: =IF($F13<>"OK","",I13/HorasDia) | L13: =IF($F13<>"OK","",H13/HorasDia) | M13: =IF($F13<>"OK","",IF(UPPER(TRIM($D13))="NO",INDEX(Cat_TMax,MATCH($C13,Cat_Nombre,0)),INDEX(Cat_TMin,MATCH($C13,Cat_Nombre,0)))) | N13: =IF($F13<>"OK","",INDEX(Cat_TMax,MATCH($C13,Cat_Nombre,0))) | O13: =IF($F13<>"OK","",INDEX(Cat_POpus,MATCH($C13,Cat_Nombre,0))) | P13: =IF($F13<>"OK","",M13/1000000*((1-O13)*UsdM_Sonnet+O13*UsdM_Opus)) | Q13: =IF($F13<>"OK","",N13/1000000*((1-O13)*UsdM_Sonnet+O13*UsdM_Opus)) | R13: =IF($F13<>"OK","",G13*TarifaHora) | S13: =IF($F13<>"OK","",H13*TarifaHora) | T13: =IF($F13<>"OK","",IF(COUNTIFS($A$2:$A13,$A13,$F$2:$F13,"OK")=1,MAX($T$1:$T12)+1,""))
F14: =IF(AND($A14="",$B14="",$C14=""),"",IF($A14="","⚠ Falta hito",IF(ISNA(MATCH($C14,Cat_Nombre,0)),"⚠ Categoría inválida","OK"))) | G14: =IF($F14<>"OK","",IF(UPPER(TRIM($D14))="NO",INDEX(Cat_HMax,MATCH($C14,Cat_Nombre,0)),INDEX(Cat_HMin,MATCH($C14,Cat_Nombre,0)))) | H14: =IF($F14<>"OK","",INDEX(Cat_HMax,MATCH($C14,Cat_Nombre,0))) | I14: =IF($F14<>"OK","",(G14+H14)/2) | J14: =IF($F14<>"OK","",G14/HorasDia) | K14: =IF($F14<>"OK","",I14/HorasDia) | L14: =IF($F14<>"OK","",H14/HorasDia) | M14: =IF($F14<>"OK","",IF(UPPER(TRIM($D14))="NO",INDEX(Cat_TMax,MATCH($C14,Cat_Nombre,0)),INDEX(Cat_TMin,MATCH($C14,Cat_Nombre,0)))) | N14: =IF($F14<>"OK","",INDEX(Cat_TMax,MATCH($C14,Cat_Nombre,0))) | O14: =IF($F14<>"OK","",INDEX(Cat_POpus,MATCH($C14,Cat_Nombre,0))) | P14: =IF($F14<>"OK","",M14/1000000*((1-O14)*UsdM_Sonnet+O14*UsdM_Opus)) | Q14: =IF($F14<>"OK","",N14/1000000*((1-O14)*UsdM_Sonnet+O14*UsdM_Opus)) | R14: =IF($F14<>"OK","",G14*TarifaHora) | S14: =IF($F14<>"OK","",H14*TarifaHora) | T14: =IF($F14<>"OK","",IF(COUNTIFS($A$2:$A14,$A14,$F$2:$F14,"OK")=1,MAX($T$1:$T13)+1,""))
F15: =IF(AND($A15="",$B15="",$C15=""),"",IF($A15="","⚠ Falta hito",IF(ISNA(MATCH($C15,Cat_Nombre,0)),"⚠ Categoría inválida","OK"))) | G15: =IF($F15<>"OK","",IF(UPPER(TRIM($D15))="NO",INDEX(Cat_HMax,MATCH($C15,Cat_Nombre,0)),INDEX(Cat_HMin,MATCH($C15,Cat_Nombre,0)))) | H15: =IF($F15<>"OK","",INDEX(Cat_HMax,MATCH($C15,Cat_Nombre,0))) | I15: =IF($F15<>"OK","",(G15+H15)/2) | J15: =IF($F15<>"OK","",G15/HorasDia) | K15: =IF($F15<>"OK","",I15/HorasDia) | L15: =IF($F15<>"OK","",H15/HorasDia) | M15: =IF($F15<>"OK","",IF(UPPER(TRIM($D15))="NO",INDEX(Cat_TMax,MATCH($C15,Cat_Nombre,0)),INDEX(Cat_TMin,MATCH($C15,Cat_Nombre,0)))) | N15: =IF($F15<>"OK","",INDEX(Cat_TMax,MATCH($C15,Cat_Nombre,0))) | O15: =IF($F15<>"OK","",INDEX(Cat_POpus,MATCH($C15,Cat_Nombre,0))) | P15: =IF($F15<>"OK","",M15/1000000*((1-O15)*UsdM_Sonnet+O15*UsdM_Opus)) | Q15: =IF($F15<>"OK","",N15/1000000*((1-O15)*UsdM_Sonnet+O15*UsdM_Opus)) | R15: =IF($F15<>"OK","",G15*TarifaHora) | S15: =IF($F15<>"OK","",H15*TarifaHora) | T15: =IF($F15<>"OK","",IF(COUNTIFS($A$2:$A15,$A15,$F$2:$F15,"OK")=1,MAX($T$1:$T14)+1,""))
F16: =IF(AND($A16="",$B16="",$C16=""),"",IF($A16="","⚠ Falta hito",IF(ISNA(MATCH($C16,Cat_Nombre,0)),"⚠ Categoría inválida","OK"))) | G16: =IF($F16<>"OK","",IF(UPPER(TRIM($D16))="NO",INDEX(Cat_HMax,MATCH($C16,Cat_Nombre,0)),INDEX(Cat_HMin,MATCH($C16,Cat_Nombre,0)))) | H16: =IF($F16<>"OK","",INDEX(Cat_HMax,MATCH($C16,Cat_Nombre,0))) | I16: =IF($F16<>"OK","",(G16+H16)/2) | J16: =IF($F16<>"OK","",G16/HorasDia) | K16: =IF($F16<>"OK","",I16/HorasDia) | L16: =IF($F16<>"OK","",H16/HorasDia) | M16: =IF($F16<>"OK","",IF(UPPER(TRIM($D16))="NO",INDEX(Cat_TMax,MATCH($C16,Cat_Nombre,0)),INDEX(Cat_TMin,MATCH($C16,Cat_Nombre,0)))) | N16: =IF($F16<>"OK","",INDEX(Cat_TMax,MATCH($C16,Cat_Nombre,0))) | O16: =IF($F16<>"OK","",INDEX(Cat_POpus,MATCH($C16,Cat_Nombre,0))) | P16: =IF($F16<>"OK","",M16/1000000*((1-O16)*UsdM_Sonnet+O16*UsdM_Opus)) | Q16: =IF($F16<>"OK","",N16/1000000*((1-O16)*UsdM_Sonnet+O16*UsdM_Opus)) | R16: =IF($F16<>"OK","",G16*TarifaHora) | S16: =IF($F16<>"OK","",H16*TarifaHora) | T16: =IF($F16<>"OK","",IF(COUNTIFS($A$2:$A16,$A16,$F$2:$F16,"OK")=1,MAX($T$1:$T15)+1,""))
F17: =IF(AND($A17="",$B17="",$C17=""),"",IF($A17="","⚠ Falta hito",IF(ISNA(MATCH($C17,Cat_Nombre,0)),"⚠ Categoría inválida","OK"))) | G17: =IF($F17<>"OK","",IF(UPPER(TRIM($D17))="NO",INDEX(Cat_HMax,MATCH($C17,Cat_Nombre,0)),INDEX(Cat_HMin,MATCH($C17,Cat_Nombre,0)))) | H17: =IF($F17<>"OK","",INDEX(Cat_HMax,MATCH($C17,Cat_Nombre,0))) | I17: =IF($F17<>"OK","",(G17+H17)/2) | J17: =IF($F17<>"OK","",G17/HorasDia) | K17: =IF($F17<>"OK","",I17/HorasDia) | L17: =IF($F17<>"OK","",H17/HorasDia) | M17: =IF($F17<>"OK","",IF(UPPER(TRIM($D17))="NO",INDEX(Cat_TMax,MATCH($C17,Cat_Nombre,0)),INDEX(Cat_TMin,MATCH($C17,Cat_Nombre,0)))) | N17: =IF($F17<>"OK","",INDEX(Cat_TMax,MATCH($C17,Cat_Nombre,0))) | O17: =IF($F17<>"OK","",INDEX(Cat_POpus,MATCH($C17,Cat_Nombre,0))) | P17: =IF($F17<>"OK","",M17/1000000*((1-O17)*UsdM_Sonnet+O17*UsdM_Opus)) | Q17: =IF($F17<>"OK","",N17/1000000*((1-O17)*UsdM_Sonnet+O17*UsdM_Opus)) | R17: =IF($F17<>"OK","",G17*TarifaHora) | S17: =IF($F17<>"OK","",H17*TarifaHora) | T17: =IF($F17<>"OK","",IF(COUNTIFS($A$2:$A17,$A17,$F$2:$F17,"OK")=1,MAX($T$1:$T16)+1,""))
F18: =IF(AND($A18="",$B18="",$C18=""),"",IF($A18="","⚠ Falta hito",IF(ISNA(MATCH($C18,Cat_Nombre,0)),"⚠ Categoría inválida","OK"))) | G18: =IF($F18<>"OK","",IF(UPPER(TRIM($D18))="NO",INDEX(Cat_HMax,MATCH($C18,Cat_Nombre,0)),INDEX(Cat_HMin,MATCH($C18,Cat_Nombre,0)))) | H18: =IF($F18<>"OK","",INDEX(Cat_HMax,MATCH($C18,Cat_Nombre,0))) | I18: =IF($F18<>"OK","",(G18+H18)/2) | J18: =IF($F18<>"OK","",G18/HorasDia) | K18: =IF($F18<>"OK","",I18/HorasDia) | L18: =IF($F18<>"OK","",H18/HorasDia) | M18: =IF($F18<>"OK","",IF(UPPER(TRIM($D18))="NO",INDEX(Cat_TMax,MATCH($C18,Cat_Nombre,0)),INDEX(Cat_TMin,MATCH($C18,Cat_Nombre,0)))) | N18: =IF($F18<>"OK","",INDEX(Cat_TMax,MATCH($C18,Cat_Nombre,0))) | O18: =IF($F18<>"OK","",INDEX(Cat_POpus,MATCH($C18,Cat_Nombre,0))) | P18: =IF($F18<>"OK","",M18/1000000*((1-O18)*UsdM_Sonnet+O18*UsdM_Opus)) | Q18: =IF($F18<>"OK","",N18/1000000*((1-O18)*UsdM_Sonnet+O18*UsdM_Opus)) | R18: =IF($F18<>"OK","",G18*TarifaHora) | S18: =IF($F18<>"OK","",H18*TarifaHora) | T18: =IF($F18<>"OK","",IF(COUNTIFS($A$2:$A18,$A18,$F$2:$F18,"OK")=1,MAX($T$1:$T17)+1,""))
F19: =IF(AND($A19="",$B19="",$C19=""),"",IF($A19="","⚠ Falta hito",IF(ISNA(MATCH($C19,Cat_Nombre,0)),"⚠ Categoría inválida","OK"))) | G19: =IF($F19<>"OK","",IF(UPPER(TRIM($D19))="NO",INDEX(Cat_HMax,MATCH($C19,Cat_Nombre,0)),INDEX(Cat_HMin,MATCH($C19,Cat_Nombre,0)))) | H19: =IF($F19<>"OK","",INDEX(Cat_HMax,MATCH($C19,Cat_Nombre,0))) | I19: =IF($F19<>"OK","",(G19+H19)/2) | J19: =IF($F19<>"OK","",G19/HorasDia) | K19: =IF($F19<>"OK","",I19/HorasDia) | L19: =IF($F19<>"OK","",H19/HorasDia) | M19: =IF($F19<>"OK","",IF(UPPER(TRIM($D19))="NO",INDEX(Cat_TMax,MATCH($C19,Cat_Nombre,0)),INDEX(Cat_TMin,MATCH($C19,Cat_Nombre,0)))) | N19: =IF($F19<>"OK","",INDEX(Cat_TMax,MATCH($C19,Cat_Nombre,0))) | O19: =IF($F19<>"OK","",INDEX(Cat_POpus,MATCH($C19,Cat_Nombre,0))) | P19: =IF($F19<>"OK","",M19/1000000*((1-O19)*UsdM_Sonnet+O19*UsdM_Opus)) | Q19: =IF($F19<>"OK","",N19/1000000*((1-O19)*UsdM_Sonnet+O19*UsdM_Opus)) | R19: =IF($F19<>"OK","",G19*TarifaHora) | S19: =IF($F19<>"OK","",H19*TarifaHora) | T19: =IF($F19<>"OK","",IF(COUNTIFS($A$2:$A19,$A19,$F$2:$F19,"OK")=1,MAX($T$1:$T18)+1,""))
F20: =IF(AND($A20="",$B20="",$C20=""),"",IF($A20="","⚠ Falta hito",IF(ISNA(MATCH($C20,Cat_Nombre,0)),"⚠ Categoría inválida","OK"))) | G20: =IF($F20<>"OK","",IF(UPPER(TRIM($D20))="NO",INDEX(Cat_HMax,MATCH($C20,Cat_Nombre,0)),INDEX(Cat_HMin,MATCH($C20,Cat_Nombre,0)))) | H20: =IF($F20<>"OK","",INDEX(Cat_HMax,MATCH($C20,Cat_Nombre,0))) | I20: =IF($F20<>"OK","",(G20+H20)/2) | J20: =IF($F20<>"OK","",G20/HorasDia) | K20: =IF($F20<>"OK","",I20/HorasDia) | L20: =IF($F20<>"OK","",H20/HorasDia) | M20: =IF($F20<>"OK","",IF(UPPER(TRIM($D20))="NO",INDEX(Cat_TMax,MATCH($C20,Cat_Nombre,0)),INDEX(Cat_TMin,MATCH($C20,Cat_Nombre,0)))) | N20: =IF($F20<>"OK","",INDEX(Cat_TMax,MATCH($C20,Cat_Nombre,0))) | O20: =IF($F20<>"OK","",INDEX(Cat_POpus,MATCH($C20,Cat_Nombre,0))) | P20: =IF($F20<>"OK","",M20/1000000*((1-O20)*UsdM_Sonnet+O20*UsdM_Opus)) | Q20: =IF($F20<>"OK","",N20/1000000*((1-O20)*UsdM_Sonnet+O20*UsdM_Opus)) | R20: =IF($F20<>"OK","",G20*TarifaHora) | S20: =IF($F20<>"OK","",H20*TarifaHora) | T20: =IF($F20<>"OK","",IF(COUNTIFS($A$2:$A20,$A20,$F$2:$F20,"OK")=1,MAX($T$1:$T19)+1,""))
F21: =IF(AND($A21="",$B21="",$C21=""),"",IF($A21="","⚠ Falta hito",IF(ISNA(MATCH($C21,Cat_Nombre,0)),"⚠ Categoría inválida","OK"))) | G21: =IF($F21<>"OK","",IF(UPPER(TRIM($D21))="NO",INDEX(Cat_HMax,MATCH($C21,Cat_Nombre,0)),INDEX(Cat_HMin,MATCH($C21,Cat_Nombre,0)))) | H21: =IF($F21<>"OK","",INDEX(Cat_HMax,MATCH($C21,Cat_Nombre,0))) | I21: =IF($F21<>"OK","",(G21+H21)/2) | J21: =IF($F21<>"OK","",G21/HorasDia) | K21: =IF($F21<>"OK","",I21/HorasDia) | L21: =IF($F21<>"OK","",H21/HorasDia) | M21: =IF($F21<>"OK","",IF(UPPER(TRIM($D21))="NO",INDEX(Cat_TMax,MATCH($C21,Cat_Nombre,0)),INDEX(Cat_TMin,MATCH($C21,Cat_Nombre,0)))) | N21: =IF($F21<>"OK","",INDEX(Cat_TMax,MATCH($C21,Cat_Nombre,0))) | O21: =IF($F21<>"OK","",INDEX(Cat_POpus,MATCH($C21,Cat_Nombre,0))) | P21: =IF($F21<>"OK","",M21/1000000*((1-O21)*UsdM_Sonnet+O21*UsdM_Opus)) | Q21: =IF($F21<>"OK","",N21/1000000*((1-O21)*UsdM_Sonnet+O21*UsdM_Opus)) | R21: =IF($F21<>"OK","",G21*TarifaHora) | S21: =IF($F21<>"OK","",H21*TarifaHora) | T21: =IF($F21<>"OK","",IF(COUNTIFS($A$2:$A21,$A21,$F$2:$F21,"OK")=1,MAX($T$1:$T20)+1,""))
... F501: =IF(AND($A501="",$B501="",$C501=""),"",IF($A501="","⚠ Falta hito",IF(ISNA(MATCH($C501,Cat_Nombre,0)),"⚠ Categoría inválida","OK"))) | G501: =IF($F501<>"OK","",IF(UPPER(TRIM($D501))="NO",INDEX(Cat_HMax,MATCH($C501,Cat_Nombre,0)),INDEX(Cat_HMin,MATCH($C501,Cat_Nombre,0)))) | H501: =IF($F501<>"OK","",INDEX(Cat_HMax,MATCH($C501,Cat_Nombre,0))) | I501: =IF($F501<>"OK","",(G501+H501)/2) | J501: =IF($F501<>"OK","",G501/HorasDia) | K501: =IF($F501<>"OK","",I501/HorasDia) | L501: =IF($F501<>"OK","",H501/HorasDia) | M501: =IF($F501<>"OK","",IF(UPPER(TRIM($D501))="NO",INDEX(Cat_TMax,MATCH($C501,Cat_Nombre,0)),INDEX(Cat_TMin,MATCH($C501,Cat_Nombre,0)))) | N501: =IF($F501<>"OK","",INDEX(Cat_TMax,MATCH($C501,Cat_Nombre,0))) | O501: =IF($F501<>"OK","",INDEX(Cat_POpus,MATCH($C501,Cat_Nombre,0))) | P501: =IF($F501<>"OK","",M501/1000000*((1-O501)*UsdM_Sonnet+O501*UsdM_Opus)) | Q501: =IF($F501<>"OK","",N501/1000000*((1-O501)*UsdM_Sonnet+O501*UsdM_Opus)) | R501: =IF($F501<>"OK","",G501*TarifaHora) | S501: =IF($F501<>"OK","",H501*TarifaHora) | T501: =IF($F501<>"OK","",IF(COUNTIFS($A$2:$A501,$A501,$F$2:$F501,"OK")=1,MAX($T$1:$T500)+1,""))

Sheet Cotización
A1: Cotización (uso interno)
A2: Proyecto | D2: =IF(COUNTIF(Features!$F:$F,"⚠*")=0,"","⚠ Hay "&COUNTIF(Features!$F:$F,"⚠*")&" feature(s) con error en la hoja Features (no se incluyen)")
A3: Cliente
A4: Fecha
A6: # | B6: Hito | C6: Nº features | D6: Días mín | E6: Días promedio | F6: Días pesimista | G6: Días comprometidos | H6: Horas comprometidas | I6: Costo tiempo comprometido | J6: Costo IA mín | K6: Costo IA máx | L6: Costo total mín | M6: Costo total máx | N6: Precio sugerido
A7: 1 | B7: =IFERROR(INDEX(Features!$A:$A,MATCH($A7,Features!$T:$T,0)),"") | C7: =IF($B7="","",COUNTIFS(Features!$A:$A,$B7,Features!$F:$F,"OK")) | D7: =IF($B7="","",SUMIFS(Features!$J:$J,Features!$A:$A,$B7,Features!$F:$F,"OK")) | E7: =IF($B7="","",SUMIFS(Features!$K:$K,Features!$A:$A,$B7,Features!$F:$F,"OK")) | F7: =IF($B7="","",SUMIFS(Features!$L:$L,Features!$A:$A,$B7,Features!$F:$F,"OK")) | G7: =IF($B7="","",E7+FactorColchon*(F7-E7)) | H7: =IF($B7="","",G7*HorasDia) | I7: =IF($B7="","",H7*TarifaHora) | J7: =IF($B7="","",SUMIFS(Features!$P:$P,Features!$A:$A,$B7,Features!$F:$F,"OK")) | K7: =IF($B7="","",SUMIFS(Features!$Q:$Q,Features!$A:$A,$B7,Features!$F:$F,"OK")) | L7: =IF($B7="","",I7+J7) | M7: =IF($B7="","",I7+K7) | N7: =IF($B7="","",M7*(1+Margen))
A8: 2 | B8: =IFERROR(INDEX(Features!$A:$A,MATCH($A8,Features!$T:$T,0)),"") | C8: =IF($B8="","",COUNTIFS(Features!$A:$A,$B8,Features!$F:$F,"OK")) | D8: =IF($B8="","",SUMIFS(Features!$J:$J,Features!$A:$A,$B8,Features!$F:$F,"OK")) | E8: =IF($B8="","",SUMIFS(Features!$K:$K,Features!$A:$A,$B8,Features!$F:$F,"OK")) | F8: =IF($B8="","",SUMIFS(Features!$L:$L,Features!$A:$A,$B8,Features!$F:$F,"OK")) | G8: =IF($B8="","",E8+FactorColchon*(F8-E8)) | H8: =IF($B8="","",G8*HorasDia) | I8: =IF($B8="","",H8*TarifaHora) | J8: =IF($B8="","",SUMIFS(Features!$P:$P,Features!$A:$A,$B8,Features!$F:$F,"OK")) | K8: =IF($B8="","",SUMIFS(Features!$Q:$Q,Features!$A:$A,$B8,Features!$F:$F,"OK")) | L8: =IF($B8="","",I8+J8) | M8: =IF($B8="","",I8+K8) | N8: =IF($B8="","",M8*(1+Margen))
A9: 3 | B9: =IFERROR(INDEX(Features!$A:$A,MATCH($A9,Features!$T:$T,0)),"") | C9: =IF($B9="","",COUNTIFS(Features!$A:$A,$B9,Features!$F:$F,"OK")) | D9: =IF($B9="","",SUMIFS(Features!$J:$J,Features!$A:$A,$B9,Features!$F:$F,"OK")) | E9: =IF($B9="","",SUMIFS(Features!$K:$K,Features!$A:$A,$B9,Features!$F:$F,"OK")) | F9: =IF($B9="","",SUMIFS(Features!$L:$L,Features!$A:$A,$B9,Features!$F:$F,"OK")) | G9: =IF($B9="","",E9+FactorColchon*(F9-E9)) | H9: =IF($B9="","",G9*HorasDia) | I9: =IF($B9="","",H9*TarifaHora) | J9: =IF($B9="","",SUMIFS(Features!$P:$P,Features!$A:$A,$B9,Features!$F:$F,"OK")) | K9: =IF($B9="","",SUMIFS(Features!$Q:$Q,Features!$A:$A,$B9,Features!$F:$F,"OK")) | L9: =IF($B9="","",I9+J9) | M9: =IF($B9="","",I9+K9) | N9: =IF($B9="","",M9*(1+Margen))
A10: 4 | B10: =IFERROR(INDEX(Features!$A:$A,MATCH($A10,Features!$T:$T,0)),"") | C10: =IF($B10="","",COUNTIFS(Features!$A:$A,$B10,Features!$F:$F,"OK")) | D10: =IF($B10="","",SUMIFS(Features!$J:$J,Features!$A:$A,$B10,Features!$F:$F,"OK")) | E10: =IF($B10="","",SUMIFS(Features!$K:$K,Features!$A:$A,$B10,Features!$F:$F,"OK")) | F10: =IF($B10="","",SUMIFS(Features!$L:$L,Features!$A:$A,$B10,Features!$F:$F,"OK")) | G10: =IF($B10="","",E10+FactorColchon*(F10-E10)) | H10: =IF($B10="","",G10*HorasDia) | I10: =IF($B10="","",H10*TarifaHora) | J10: =IF($B10="","",SUMIFS(Features!$P:$P,Features!$A:$A,$B10,Features!$F:$F,"OK")) | K10: =IF($B10="","",SUMIFS(Features!$Q:$Q,Features!$A:$A,$B10,Features!$F:$F,"OK")) | L10: =IF($B10="","",I10+J10) | M10: =IF($B10="","",I10+K10) | N10: =IF($B10="","",M10*(1+Margen))
A11: 5 | B11: =IFERROR(INDEX(Features!$A:$A,MATCH($A11,Features!$T:$T,0)),"") | C11: =IF($B11="","",COUNTIFS(Features!$A:$A,$B11,Features!$F:$F,"OK")) | D11: =IF($B11="","",SUMIFS(Features!$J:$J,Features!$A:$A,$B11,Features!$F:$F,"OK")) | E11: =IF($B11="","",SUMIFS(Features!$K:$K,Features!$A:$A,$B11,Features!$F:$F,"OK")) | F11: =IF($B11="","",SUMIFS(Features!$L:$L,Features!$A:$A,$B11,Features!$F:$F,"OK")) | G11: =IF($B11="","",E11+FactorColchon*(F11-E11)) | H11: =IF($B11="","",G11*HorasDia) | I11: =IF($B11="","",H11*TarifaHora) | J11: =IF($B11="","",SUMIFS(Features!$P:$P,Features!$A:$A,$B11,Features!$F:$F,"OK")) | K11: =IF($B11="","",SUMIFS(Features!$Q:$Q,Features!$A:$A,$B11,Features!$F:$F,"OK")) | L11: =IF($B11="","",I11+J11) | M11: =IF($B11="","",I11+K11) | N11: =IF($B11="","",M11*(1+Margen))
A12: 6 | B12: =IFERROR(INDEX(Features!$A:$A,MATCH($A12,Features!$T:$T,0)),"") | C12: =IF($B12="","",COUNTIFS(Features!$A:$A,$B12,Features!$F:$F,"OK")) | D12: =IF($B12="","",SUMIFS(Features!$J:$J,Features!$A:$A,$B12,Features!$F:$F,"OK")) | E12: =IF($B12="","",SUMIFS(Features!$K:$K,Features!$A:$A,$B12,Features!$F:$F,"OK")) | F12: =IF($B12="","",SUMIFS(Features!$L:$L,Features!$A:$A,$B12,Features!$F:$F,"OK")) | G12: =IF($B12="","",E12+FactorColchon*(F12-E12)) | H12: =IF($B12="","",G12*HorasDia) | I12: =IF($B12="","",H12*TarifaHora) | J12: =IF($B12="","",SUMIFS(Features!$P:$P,Features!$A:$A,$B12,Features!$F:$F,"OK")) | K12: =IF($B12="","",SUMIFS(Features!$Q:$Q,Features!$A:$A,$B12,Features!$F:$F,"OK")) | L12: =IF($B12="","",I12+J12) | M12: =IF($B12="","",I12+K12) | N12: =IF($B12="","",M12*(1+Margen))
A13: 7 | B13: =IFERROR(INDEX(Features!$A:$A,MATCH($A13,Features!$T:$T,0)),"") | C13: =IF($B13="","",COUNTIFS(Features!$A:$A,$B13,Features!$F:$F,"OK")) | D13: =IF($B13="","",SUMIFS(Features!$J:$J,Features!$A:$A,$B13,Features!$F:$F,"OK")) | E13: =IF($B13="","",SUMIFS(Features!$K:$K,Features!$A:$A,$B13,Features!$F:$F,"OK")) | F13: =IF($B13="","",SUMIFS(Features!$L:$L,Features!$A:$A,$B13,Features!$F:$F,"OK")) | G13: =IF($B13="","",E13+FactorColchon*(F13-E13)) | H13: =IF($B13="","",G13*HorasDia) | I13: =IF($B13="","",H13*TarifaHora) | J13: =IF($B13="","",SUMIFS(Features!$P:$P,Features!$A:$A,$B13,Features!$F:$F,"OK")) | K13: =IF($B13="","",SUMIFS(Features!$Q:$Q,Features!$A:$A,$B13,Features!$F:$F,"OK")) | L13: =IF($B13="","",I13+J13) | M13: =IF($B13="","",I13+K13) | N13: =IF($B13="","",M13*(1+Margen))
A14: 8 | B14: =IFERROR(INDEX(Features!$A:$A,MATCH($A14,Features!$T:$T,0)),"") | C14: =IF($B14="","",COUNTIFS(Features!$A:$A,$B14,Features!$F:$F,"OK")) | D14: =IF($B14="","",SUMIFS(Features!$J:$J,Features!$A:$A,$B14,Features!$F:$F,"OK")) | E14: =IF($B14="","",SUMIFS(Features!$K:$K,Features!$A:$A,$B14,Features!$F:$F,"OK")) | F14: =IF($B14="","",SUMIFS(Features!$L:$L,Features!$A:$A,$B14,Features!$F:$F,"OK")) | G14: =IF($B14="","",E14+FactorColchon*(F14-E14)) | H14: =IF($B14="","",G14*HorasDia) | I14: =IF($B14="","",H14*TarifaHora) | J14: =IF($B14="","",SUMIFS(Features!$P:$P,Features!$A:$A,$B14,Features!$F:$F,"OK")) | K14: =IF($B14="","",SUMIFS(Features!$Q:$Q,Features!$A:$A,$B14,Features!$F:$F,"OK")) | L14: =IF($B14="","",I14+J14) | M14: =IF($B14="","",I14+K14) | N14: =IF($B14="","",M14*(1+Margen))
A15: 9 | B15: =IFERROR(INDEX(Features!$A:$A,MATCH($A15,Features!$T:$T,0)),"") | C15: =IF($B15="","",COUNTIFS(Features!$A:$A,$B15,Features!$F:$F,"OK")) | D15: =IF($B15="","",SUMIFS(Features!$J:$J,Features!$A:$A,$B15,Features!$F:$F,"OK")) | E15: =IF($B15="","",SUMIFS(Features!$K:$K,Features!$A:$A,$B15,Features!$F:$F,"OK")) | F15: =IF($B15="","",SUMIFS(Features!$L:$L,Features!$A:$A,$B15,Features!$F:$F,"OK")) | G15: =IF($B15="","",E15+FactorColchon*(F15-E15)) | H15: =IF($B15="","",G15*HorasDia) | I15: =IF($B15="","",H15*TarifaHora) | J15: =IF($B15="","",SUMIFS(Features!$P:$P,Features!$A:$A,$B15,Features!$F:$F,"OK")) | K15: =IF($B15="","",SUMIFS(Features!$Q:$Q,Features!$A:$A,$B15,Features!$F:$F,"OK")) | L15: =IF($B15="","",I15+J15) | M15: =IF($B15="","",I15+K15) | N15: =IF($B15="","",M15*(1+Margen))
A16: 10 | B16: =IFERROR(INDEX(Features!$A:$A,MATCH($A16,Features!$T:$T,0)),"") | C16: =IF($B16="","",COUNTIFS(Features!$A:$A,$B16,Features!$F:$F,"OK")) | D16: =IF($B16="","",SUMIFS(Features!$J:$J,Features!$A:$A,$B16,Features!$F:$F,"OK")) | E16: =IF($B16="","",SUMIFS(Features!$K:$K,Features!$A:$A,$B16,Features!$F:$F,"OK")) | F16: =IF($B16="","",SUMIFS(Features!$L:$L,Features!$A:$A,$B16,Features!$F:$F,"OK")) | G16: =IF($B16="","",E16+FactorColchon*(F16-E16)) | H16: =IF($B16="","",G16*HorasDia) | I16: =IF($B16="","",H16*TarifaHora) | J16: =IF($B16="","",SUMIFS(Features!$P:$P,Features!$A:$A,$B16,Features!$F:$F,"OK")) | K16: =IF($B16="","",SUMIFS(Features!$Q:$Q,Features!$A:$A,$B16,Features!$F:$F,"OK")) | L16: =IF($B16="","",I16+J16) | M16: =IF($B16="","",I16+K16) | N16: =IF($B16="","",M16*(1+Margen))
A17: 11 | B17: =IFERROR(INDEX(Features!$A:$A,MATCH($A17,Features!$T:$T,0)),"") | C17: =IF($B17="","",COUNTIFS(Features!$A:$A,$B17,Features!$F:$F,"OK")) | D17: =IF($B17="","",SUMIFS(Features!$J:$J,Features!$A:$A,$B17,Features!$F:$F,"OK")) | E17: =IF($B17="","",SUMIFS(Features!$K:$K,Features!$A:$A,$B17,Features!$F:$F,"OK")) | F17: =IF($B17="","",SUMIFS(Features!$L:$L,Features!$A:$A,$B17,Features!$F:$F,"OK")) | G17: =IF($B17="","",E17+FactorColchon*(F17-E17)) | H17: =IF($B17="","",G17*HorasDia) | I17: =IF($B17="","",H17*TarifaHora) | J17: =IF($B17="","",SUMIFS(Features!$P:$P,Features!$A:$A,$B17,Features!$F:$F,"OK")) | K17: =IF($B17="","",SUMIFS(Features!$Q:$Q,Features!$A:$A,$B17,Features!$F:$F,"OK")) | L17: =IF($B17="","",I17+J17) | M17: =IF($B17="","",I17+K17) | N17: =IF($B17="","",M17*(1+Margen))
A18: 12 | B18: =IFERROR(INDEX(Features!$A:$A,MATCH($A18,Features!$T:$T,0)),"") | C18: =IF($B18="","",COUNTIFS(Features!$A:$A,$B18,Features!$F:$F,"OK")) | D18: =IF($B18="","",SUMIFS(Features!$J:$J,Features!$A:$A,$B18,Features!$F:$F,"OK")) | E18: =IF($B18="","",SUMIFS(Features!$K:$K,Features!$A:$A,$B18,Features!$F:$F,"OK")) | F18: =IF($B18="","",SUMIFS(Features!$L:$L,Features!$A:$A,$B18,Features!$F:$F,"OK")) | G18: =IF($B18="","",E18+FactorColchon*(F18-E18)) | H18: =IF($B18="","",G18*HorasDia) | I18: =IF($B18="","",H18*TarifaHora) | J18: =IF($B18="","",SUMIFS(Features!$P:$P,Features!$A:$A,$B18,Features!$F:$F,"OK")) | K18: =IF($B18="","",SUMIFS(Features!$Q:$Q,Features!$A:$A,$B18,Features!$F:$F,"OK")) | L18: =IF($B18="","",I18+J18) | M18: =IF($B18="","",I18+K18) | N18: =IF($B18="","",M18*(1+Margen))
... A56: 50 | B56: =IFERROR(INDEX(Features!$A:$A,MATCH($A56,Features!$T:$T,0)),"") | C56: =IF($B56="","",COUNTIFS(Features!$A:$A,$B56,Features!$F:$F,"OK")) | D56: =IF($B56="","",SUMIFS(Features!$J:$J,Features!$A:$A,$B56,Features!$F:$F,"OK")) | E56: =IF($B56="","",SUMIFS(Features!$K:$K,Features!$A:$A,$B56,Features!$F:$F,"OK")) | F56: =IF($B56="","",SUMIFS(Features!$L:$L,Features!$A:$A,$B56,Features!$F:$F,"OK")) | G56: =IF($B56="","",E56+FactorColchon*(F56-E56)) | H56: =IF($B56="","",G56*HorasDia) | I56: =IF($B56="","",H56*TarifaHora) | J56: =IF($B56="","",SUMIFS(Features!$P:$P,Features!$A:$A,$B56,Features!$F:$F,"OK")) | K56: =IF($B56="","",SUMIFS(Features!$Q:$Q,Features!$A:$A,$B56,Features!$F:$F,"OK")) | L56: =IF($B56="","",I56+J56) | M56: =IF($B56="","",I56+K56) | N56: =IF($B56="","",M56*(1+Margen))
B57: TOTAL PROYECTO | C57: =SUM(C7:C56) | D57: =SUM(D7:D56) | E57: =SUM(E7:E56) | F57: =SUM(F7:F56) | G57: =SUM(G7:G56) | H57: =SUM(H7:H56) | I57: =SUM(I7:I56) | J57: =SUM(J7:J56) | ... N57: =SUM(N7:N56)
A59: Días comprometidos y costo de tiempo = compromiso de entrega (precio fijo por hito). El costo de IA se mantiene como rango.

Sheet Propuesta cliente
A1: Propuesta económica
A2: Proyecto | B2: =IF(Cotización!B2="","",Cotización!B2)
A3: Cliente | B3: =IF(Cotización!B3="","",Cotización!B3)
A4: Fecha | B4: =IF(Cotización!B4="","",Cotización!B4)
A6: Hito | B6: Días de entrega comprometidos | C6: ="Precio ("&MonedaCliente&")"
A7: =Cotización!B7 | B7: =IF(Cotización!B7="","",Cotización!G7) | C7: =IF(Cotización!B7="","",IF(MonedaCliente="PEN",Cotización!N7*TipoCambio,Cotización!N7))
A8: =Cotización!B8 | B8: =IF(Cotización!B8="","",Cotización!G8) | C8: =IF(Cotización!B8="","",IF(MonedaCliente="PEN",Cotización!N8*TipoCambio,Cotización!N8))
A9: =Cotización!B9 | B9: =IF(Cotización!B9="","",Cotización!G9) | C9: =IF(Cotización!B9="","",IF(MonedaCliente="PEN",Cotización!N9*TipoCambio,Cotización!N9))
A10: =Cotización!B10 | B10: =IF(Cotización!B10="","",Cotización!G10) | C10: =IF(Cotización!B10="","",IF(MonedaCliente="PEN",Cotización!N10*TipoCambio,Cotización!N10))
A11: =Cotización!B11 | B11: =IF(Cotización!B11="","",Cotización!G11) | C11: =IF(Cotización!B11="","",IF(MonedaCliente="PEN",Cotización!N11*TipoCambio,Cotización!N11))
A12: =Cotización!B12 | B12: =IF(Cotización!B12="","",Cotización!G12) | C12: =IF(Cotización!B12="","",IF(MonedaCliente="PEN",Cotización!N12*TipoCambio,Cotización!N12))
A13: =Cotización!B13 | B13: =IF(Cotización!B13="","",Cotización!G13) | C13: =IF(Cotización!B13="","",IF(MonedaCliente="PEN",Cotización!N13*TipoCambio,Cotización!N13))
A14: =Cotización!B14 | B14: =IF(Cotización!B14="","",Cotización!G14) | C14: =IF(Cotización!B14="","",IF(MonedaCliente="PEN",Cotización!N14*TipoCambio,Cotización!N14))
A15: =Cotización!B15 | B15: =IF(Cotización!B15="","",Cotización!G15) | C15: =IF(Cotización!B15="","",IF(MonedaCliente="PEN",Cotización!N15*TipoCambio,Cotización!N15))
A16: =Cotización!B16 | B16: =IF(Cotización!B16="","",Cotización!G16) | C16: =IF(Cotización!B16="","",IF(MonedaCliente="PEN",Cotización!N16*TipoCambio,Cotización!N16))
A17: =Cotización!B17 | B17: =IF(Cotización!B17="","",Cotización!G17) | C17: =IF(Cotización!B17="","",IF(MonedaCliente="PEN",Cotización!N17*TipoCambio,Cotización!N17))
A18: =Cotización!B18 | B18: =IF(Cotización!B18="","",Cotización!G18) | C18: =IF(Cotización!B18="","",IF(MonedaCliente="PEN",Cotización!N18*TipoCambio,Cotización!N18))
... A56: =Cotización!B56 | B56: =IF(Cotización!B56="","",Cotización!G56) | C56: =IF(Cotización!B56="","",IF(MonedaCliente="PEN",Cotización!N56*TipoCambio,Cotización!N56))
A57: TOTAL | B57: =SUM(B7:B56) | C57: =SUM(C7:C56)
A59: ="Precio fijo por hito, en "&MonedaCliente&". Días hábiles de trabajo efectivo."&IF(MonedaCliente="PEN"," Tipo de cambio referencial: S/ "&TEXT(TipoCambio,"0.000")&" por USD.","")

Sheet Prompt IA
A1: Copia la celda A3 completa y pégala en el LLM (reemplaza la última línea por el alcance).
A3: Actúa como estimador de proyectos de software. Divide el alcance de abajo en hitos y cada hito en features. Reglas: - Feature = unidad de trabajo con alcance propio, describible en una frase y usable/probable de punta a punta. Si necesitas "y" para unir dos cosas que no dependen entre sí, son dos features. - La configuración inicial (scaffold, autenticación, hosting/despliegue, persistencia) va en un hito propio llamado "Hito 0 - Configuración inicial". - Categoría: usa EXACTAMENTE uno de estos valores: Simple: repite un patrón ya resuelto antes en el mismo proyecto, sin reglas de negocio nuevas. Moderado: entidad o flujo nuevo con reglas de negocio propias, sobre arquitectura/patrones ya definidos. Complejo: motor reutilizable por otras partes del sistema, integración externa ya conocida con reglas nuevas, o decisión de arquitectura no trivial. Complejo primera vez: como Complejo pero sin ningún patrón previo en el proyecto (primera integración externa, primer pipeline de despliegue, primer sistema de autenticación, etc.). - Ajustes: si depende de una tecnología/integración usada por primera vez en el proyecto, sube al menos una categoría. Si solo reutiliza un motor construido en una feature anterior, baja al menos una categoría. - Confirmado: "No" si el alcance de la feature aún no está confirmado con el dueño del producto; si no, "Sí". Formato de salida (estricto): - SOLO un bloque de código con valores separados por TABULACIONES. Sin encabezado, sin explicaciones, sin numeración. - 4 columnas en este orden: Hito<TAB>Feature<TAB>Categoría<TAB>Confirmado - Una feature por línea. Repite el nombre exacto del hito en cada línea. Alcance del proyecto: <pega aquí el alcance>
